## 概述

```
程序运行时常会碰到一些异常情况，例如：

-1-做除法的时候除数为 0；
-2-用户输入年龄时输入了一个负数；
-3-用 new 运算符动态分配空间时，空间不够导致无法分配；
-4-访问数组元素时，下标越界；打开文件读取时，文件不存在。
这些异常情况，如果不能发现并加以处理，很可能会导致程序崩溃。

所谓“处理”，可以是给出错误提示信息，然后让程序沿一条不会出错的路径继续执行；也可能是不得不结束程序，但在结束前做一些必要的工作，如将内存中的数据写入文件、关闭打开的文件、释放动态分配的内存空间等。
```

## 优点

```
如果程序throw出的异常能够被正确的catch。就能够输出相关信息
斗否则就会导致
就不会导致程序的终止。

1.异常对象定义好了，相比错误码的方式可以清晰准确的展示出错误的各种信息，甚至可以包含堆栈调用 的信息，这样可以帮助更好的定位程序的bug。
2.返回错误码的传统方式有个很大的问题就是，在函数调用链中，深层的函数返回了错误，那么我们得层层返回错误，最外层才能拿到错误，而在中间一部错误则错误就可能丢失。
3.很多的第三方库都包含异常，比如boost、gtest、gmock等等常用的库，那么我们使用它们也需要使用 异常。
4.很多测试框架都使用异常，这样能更好的使用单元测试等进行白盒的测试。
5.部分函数使用异常更好处理，比如构造函数没有返回值，不方便使用错误码方式处理。比如T& operator这样的函数，如果pos越界了只能使用异常或者终止程序处理，没办法通过返回值表示错误。assert再bug版本下可以容易发现在那些地方发生了错误，而在发布工程的时候，就没有seeert这语句。所以用异常更加方便。
```



### try_catch语句的执行过程

```
1、执行 try 块中的语句，如果执行的过程中没有异常拋出，那么执行完后就执行最后一个 catch 块后面的语句，所有 catch 块中的语句都不会被执行；
2、如果 try 块执行的过程中拋出了异常，那么拋出异常后立即跳转到第一个“异常类型”和拋出的异常类型匹配的 catch 块中执行（称作异常被该 catch 块“捕获”），执行完后再跳转到最后一个 catch 块后面继续执行。

****总结：try检测异常。抛出异常。异常去和catch块匹配。。
注意：即时不throw  也会和相应的catch匹配上。。见out_of_range异常类
```

## 示例

```

#include <iostream>
using namespace std;
int main()
{
    double m ,n;
    cin >> m >> n;
    try {
        cout << "before dividing." << endl;
        if( n == 0)
            throw -1; //抛出int类型异常
        else
            cout << m / n << endl;
        cout << "after dividing." << endl;
    }
    catch(double d) {
        cout << "catch(double) " << d <<  endl;
    }
    catch(int e) {
        cout << "catch(int) " << e << endl;
    }
    cout << "finished" << endl;
    return 0;
}
```

```
9 6
before dividing.
1.5
after dividing.
finished

9 0
before dividing.
catch(int) -1
finished
注：当 n 为 0 时，try 块中会拋出一个整型异常。
拋出异常后，try 块立即停止执行。
该整型异常会被类型匹配的第一个 catch 块捕获，即进入catch(int e)块执行，该 catch 块执行完毕后，程序继续往后执行，直到正常结束。
```

## 能够捕获任何异常的 catch 语句

```
catch(...) {
    ...
}

相当于隐式匹配  当throw出的异常没有匹配的catch块时
会匹配...的catch块
```

## 异常的再拋出

```
如果一个函数在执行过程中拋出的异常在本函数内就被 catch 块捕获并处理，那么该异常就不会拋给这个函数的调用者（也称为“上一层的函数”）；如果异常在本函数中没有被处理，则它就会被拋给上一层的函数。例如下面的程序：
```

```
#include <iostream>
#include <string>
using namespace std;
class CException
{
public:
    string msg;
    CException(string s) : msg(s) {}
};
double Devide(double x, double y)
{
    if (y == 0)
        throw CException("devided by zero");
    cout << "in Devide" << endl;
    return x / y;
}
int CountTax(int salary)
{
    try {
        if (salary < 0)
            throw - 1;
        cout << "counting tax" << endl;
    }
    catch (int) {
        cout << "salary < 0" << endl;
    }
    cout << "tax counted" << endl;
    return salary * 0.15;
}
int main()
{
    double f = 1.2;
    try {
        CountTax(-1);
        f = Devide(3, 0);
        cout << "end of try block" << endl;
    }
    catch (CException e) {
        cout << e.msg << endl;
    }
    cout << "f = " << f << endl;
    cout << "finished" << endl;
    return 0;
}
```

```

salary < 0
tax counted
devided by zero
f=1.2
finished
```

## 异常规范

```
异常规格说明的目的是为了让函数使用者知道该函数可能抛出的异常有哪些。 可以在函数的后面接 throw(类型)，列出这个函数可能抛掷的所有异常类型。
void fun() throw(); void fun1() throw(int, char);

函数的后面接throw()，表示函数不抛异常。
```

### 标准异常类

```
C++ 标准库中有一些类代表异常，这些类都是从 exception 类派生而来的。常用的几个异常类如图所示

****其有what的成员函数，返回字符串形式的异常描述信息

```

![image-20210713232302487](C:\Users\Echo\AppData\Roaming\Typora\typora-user-images\image-20210713232302487.png)

### **1) bad_typeid**

```
使用 typeid 运算符时，如果其操作数是一个多态类的指针，而该指针的值为 NULL，则会拋出此异常。
```

### **2) bad_cast**

```
在用 dynamic_cast 进行从多态基类对象（或引用）到派生类的引用的强制类型转换时，如果转换是不安全的，则会拋出此异常。
```

### **3) bad_alloc**

在用 new 运算符进行动态内存分配时，如果没有足够的内存，则会引发此异常。

```
#include <iostream>
#include <stdexcept>
using namespace std;
int main()
{
    try {
        char * p = new char[0x7fffffff];  //无法分配这么多空间，会抛出异常
    }
    catch (bad_alloc & e)  {
        cerr << e.what() << endl;
    }
    return 0;
}

bad allocation
ios_base::failure
```

### **4) out_of_range**

用 vector 或 string 的 at 成员函数根据下标访问元素时，如果下标越界，则会拋出此异常。例如：

```
#include <iostream>
#include <stdexcept>
#include <vector>
#include <string>
using namespace std;
int main()
{
    vector<int> v(10);
    try {
        v.at(100) = 100;  //拋出 out_of_range 异常
    }
    catch (out_of_range & e) {
        cerr << e.what() << endl;
    }
    string s = "hello";
    try {
        char c = s.at(100);  //拋出 out_of_range 异常
    }
    catch (out_of_range & e) {
        cerr << e.what() << endl;
    }
    return 0;
}


invalid vector <T> subscript
invalid string position
```

